Workbook

Sheet Executive Summary
A1: WORKING CAPITAL MANAGEMENT ANALYSIS
A2: Comparative Study: IT vs Manufacturing Automobile Sector
A4: Study Period: FY 2021 - FY 2025 (5 Years)
A6: KEY FINDINGS - IT SECTOR
A7: Average Working Capital Turnover Ratio | B7: 3.18
A8: Average Inventory Turnover Ratio | B8: 2735.12
A9: Average Debtors Turnover Ratio | B9: 5.18
A11: KEY FINDINGS - AUTOMOBILE SECTOR
A12: Average Working Capital Turnover Ratio | B12: -12.8
A13: Average Inventory Turnover Ratio | B13: 19.34
A14: Average Debtors Turnover Ratio | B14: 25.56
A16: COMPARATIVE ANALYSIS
A17: Ratio | B17: IT Sector | C17: Auto Sector | D17: Better Sector
A18: WCTR | B18: ='IT Sector Analysis'!G10 -> 3.1804113 | C18: ='Auto Sector Analysis'!G10 -> -12.796966 | D18: =IF(B18>C18,"IT Sector","Automobile Sector") -> IT Sector
A19: ITR | B19: ='IT Sector Analysis'!G19 -> 2735.12 | C19: ='Auto Sector Analysis'!G19 -> 19.3372 | D19: =IF(B19>C19,"IT Sector","Automobile Sector") -> IT Sector
A20: DTR | B20: ='IT Sector Analysis'!G28 -> 5.1784 | C20: ='Auto Sector Analysis'!G28 -> 25.5588 | D20: =IF(B20>C20,"IT Sector","Automobile Sector") -> Automobile Sector

Sheet IT  Raw Data
B2: TCS | C2: 46106 | D2: 46105 | E2: 46104 | F2: 46103 | G2: 46102
B3: Total Current Liabilities | C3: 49182 | D3: 43061 | E3: 39324 | F3: 37901 | G3: 28525
B4: Total Current Assets | C4: 103163 | D4: 94918 | E4: 92784 | F4: 94192 | G4: 83160
B5: Working Capital | C5: =C4-C3 -> 53981 | D5: =D4-D3 -> 51857 | E5: =E4-E3 -> 53460 | F5: =F4-F3 -> 56291 | G5: =G4-G3 -> 54635
B6: Net Sales | C6: 214853 | D6: 202359 | E6: 190354 | F6: 160341 | G6: 135963
B7: Inventory Turnover Ratio | C7: 10742.65 | D7: 7494.78 | E7: 7050.15 | F7: 8439 | G7: 19423.29
B8: Debtors Turnover Ratio | C8: 4.39 | D8: 4.55 | E8: 5.24 | F8: 5.82 | G8: 5.05
B9: Working Capital Turnover Ratio | C9: =C6/C5 -> 3.9801597 | D9: =D6/D5 -> 3.9022504 | E9: =E6/E5 -> 3.5606809 | F9: =F6/F5 -> 2.8484305 | G9: =G6/G5 -> 2.4885696
B11: Infosys | C11: 46106 | D11: 46105 | E11: 46104 | F11: 46103 | G11: 46102
B12: Total Current Liabilities | C12: 31762 | D12: 27086 | E12: 27442 | F12: 24976 | G12: 17622
B13: Total Current Assets | C13: 77168 | D13: 70952 | E13: 52082 | F13: 52437 | G13: 48282
B14: Working Capital | C14: =C13-C12 -> 45406 | D14: =D13-D12 -> 43866 | E14: =E13-E12 -> 24640 | F14: =F13-F12 -> 27461 | G14: =G13-G12 -> 30660
B15: Net Sales | C15: 136592 | D15: 128933 | E15: 124014 | F15: 103940 | G15: 85912
B16: Inventory Turnover Ratio | C16: -- | D16: -- | E16: -- | F16: -- | G16: --
B17: Debtors Turnover Ratio | C17: 5.3 | D17: 5.61 | E17: 6.24 | F17: 5.88 | G17: 5.39
B18: Working Capital Turnover Ratio | C18: =C15/C14 -> 3.0082368 | D18: =D15/D14 -> 2.9392468 | E18: =E15/E14 -> 5.0330357 | F18: =F15/F14 -> 3.7850042 | G18: =G15/G14 -> 2.8020874
B20: HCL | C20: 46106 | D20: 46105 | E20: 46104 | F20: 46103 | G20: 46102
B21: Total Current Liabilities | C21: 14035 | D21: 10464 | E21: 10667 | F21: 9043 | G21: 10019
B22: Total Current Assets | C22: 29035 | D22: 29545 | E22: 28571 | F22: 26887 | G22: 27714
B23: Working Capital | C23: =C22-C21 -> 15000 | D23: =D22-D21 -> 19081 | E23: =E22-E21 -> 17904 | F23: =F22-F21 -> 17844 | G23: =G22-G21 -> 17695
B24: Net Sales | C24: 51105 | D24: 48118 | E24: 46276 | F24: 40638 | G24: 35673
B25: Inventory Turnover Ratio | C25: 4258.75 | D25: 1924.72 | E25: 1322.17 | F25: 1766.87 | G25: 1981.83
B26: Debtors Turnover Ratio | C26: 3.81 | D26: 3.84 | E26: 3.85 | F26: 4.97 | G26: 5.61
B27: Working Capital Turnover Ratio | C27: =C24/C23 -> 3.407 | D27: =D24/D23 -> 2.5217756 | E27: =E24/E23 -> 2.5846738 | F27: =F24/F23 -> 2.2774042 | G27: =G24/G23 -> 2.0159932
B29: Wipro | C29: 46106 | D29: 46105 | E29: 46104 | F29: 46103 | G29: 46102
B30: Total Current Liabilities | C30: 22489.7 | D30: 18445.4 | E30: 18842.8 | F30: 23173.7 | G30: 18132.4
B31: Total Current Assets | C31: 60225.2 | D31: 50563.8 | E31: 53977.8 | F31: 51772.2 | G31: 45379.5
B32: Working Capital | C32: =C31-C30 -> 37735.5 | D32: =D31-D30 -> 32118.4 | E32: =E31-E30 -> 35135 | F32: =F31-F30 -> 28598.5 | G32: =G31-G30 -> 27247.1
B33: Net Sales | C33: 67292.8 | D33: 66792.4 | E33: 67753.4 | F33: 59574.4 | G33: 50299.4
B34: Inventory Turnover Ratio | C34: 1081.88 | D34: 916.22 | E34: 742.1 | F34: 680.85 | G34: 552.74
B35: Debtors Turnover Ratio | C35: 6.82 | D35: 5.36 | E35: 6 | F35: 6.87 | G35: 5.81
B36: Working Capital Turnover Ratio | C36: =C33/C32 -> 1.7832757 | D36: =D33/D32 -> 2.0795681 | E36: =E33/E32 -> 1.9283734 | F36: =F33/F32 -> 2.0831302 | G36: =G33/G32 -> 1.846046
B38: Tech Mahindra | C38: 46106 | D38: 46105 | E38: 46104 | F38: 46103 | G38: 46102
B39: Total Current Liabilities | C39: 10504.1 | D39: 8838.2 | E39: 9595.5 | F39: 6636.4 | G39: 5961.3
B40: Total Current Assets | C40: 17520.2 | D40: 16781 | E40: 17343.9 | F40: 16965 | G40: 20020.2
B41: Working Capital | C41: =C40-C39 -> 7016.1 | D41: =D40-D39 -> 7942.8 | E41: =E40-E39 -> 7748.4 | F41: =F40-F39 -> 10328.6 | G41: =G40-G39 -> 14058.9
B42: Net Sales | C42: 44617.2 | D42: 42099.3 | E42: 42657.3 | F42: 34726.1 | G42: 29640.9
B43: Inventory Turnover Ratio | C43: -- | D43: -- | E43: -- | F43: -- | G43: --
B44: Debtors Turnover Ratio | C44: 4.63 | D44: 4.25 | E44: 4.26 | F44: 4.69 | G44: 5.22
B45: Working Capital Turnover Ratio | C45: =C42/C41 -> 6.3592594 | D45: =D42/D41 -> 5.3003097 | E45: =E42/E41 -> 5.5053043 | F45: =F42/F41 -> 3.3621304 | G45: =G42/G41 -> 2.1083371

Sheet Automobile Raw Data
B2: Maruti Suzuki | C2: 46106 | D2: 46105 | E2: 46104 | F2: 46103 | G2: 46102
B3: Total Current Liabilities | C3: 26720.7 | D3: 22928.7 | E3: 20099.3 | F3: 17013.7 | G3: 16106.7
B4: Total Current Assets | C4: 23252.2 | D4: 17762.4 | E4: 11599.9 | F4: 16781.2 | G4: 18526.7
B5: Working Capital | C5: =C4-C3 -> -3468.5 | D5: =D4-D3 -> -5166.3 | E5: =E4-E3 -> -8499.4 | F5: =F4-F3 -> -232.5 | G5: =G4-G3 -> 2420
B6: Net Sales | C6: 151900.1 | D6: 140932.6 | E6: 117522.9 | F6: 88295.6 | G6: 70332.5
B7: Inventory Turnover Ratio | C7: 29.65 | D7: 34.21 | E7: 27.43 | F7: 24.99 | G7: 23.06
B8: Debtors Turnover Ratio | C8: 27.27 | D8: 35.69 | E8: 44.13 | F8: 53.4 | G8: 43.26
B9: Working Capital Turnover Ratio | C9: =C6/C5 -> -43.794176 | D9: =D6/D5 -> -27.279213 | E9: =E6/E5 -> -13.8272 | F9: =F6/F5 -> -379.76602 | G9: =G6/G5 -> 29.063017
B11: Mahindra & Mahindra | C11: 46106 | D11: 46105 | E11: 46104 | F11: 46103 | G11: 46102
B12: Total Current Liabilities | C12: 32079.79 | D12: 25978.75 | E12: 26039.99 | F12: 18820.29 | G12: 15133.17
B13: Total Current Assets | C13: 47663.9 | D13: 35105.8 | E13: 34643.63 | F13: 25917.7 | G13: 20312.3
B14: Working Capital | C14: =C13-C12 -> 15584.11 | D14: =D13-D12 -> 9127.05 | E14: =E13-E12 -> 8603.64 | F14: =F13-F12 -> 7097.41 | G14: =G13-G12 -> 5179.13
B15: Net Sales | C15: 116483.68 | D15: 98763.42 | E15: 84960.26 | F15: 57445.97 | G15: 45040.98
B16: Inventory Turnover Ratio | C16: 11.27 | D16: 10.39 | E16: 9.57 | F16: 9.76 | G16: 11.39
B17: Debtors Turnover Ratio | C17: 22.67 | D17: 22.99 | E17: 24.01 | F17: 21.36 | G17: 16.86
B18: Working Capital Turnover Ratio | C18: =C15/C14 -> 7.474516 | D18: =D15/D14 -> 10.820957 | E18: =E15/E14 -> 9.8749204 | F18: =F15/F14 -> 8.0939343 | G18: =G15/G14 -> 8.6966305
B20: Bajaj Auto | C20: 46106 | D20: 46105 | E20: 46104 | F20: 46103 | G20: 46102
B21: Total Current Liabilities | C21: 9002.75 | D21: 8725.7 | E21: 5198.04 | F21: 4689.44 | G21: 5643.21
B22: Total Current Assets | C22: 13427.31 | D22: 10357.18 | E22: 8870.41 | F22: 9994.47 | G22: 14175.13
B23: Working Capital | C23: =C22-C21 -> 4424.56 | D23: =D22-D21 -> 1631.48 | E23: =E22-E21 -> 3672.37 | F23: =F22-F21 -> 5305.03 | G23: =G22-G21 -> 8531.92
B24: Net Sales | C24: 50010.31 | D24: 44685.23 | E24: 36427.6 | F24: 33144.71 | G24: 27741.08
B25: Inventory Turnover Ratio | C25: 25.54 | D25: 26.35 | E25: 26.06 | F25: 26.94 | G25: 18.57
B26: Debtors Turnover Ratio | C26: 22.71 | D26: 22.92 | E26: 22.13 | F26: 15.66 | G26: 12.49
B27: Working Capital Turnover Ratio | C27: =C24/C23 -> 11.302889 | D27: =D24/D23 -> 27.389383 | E27: =E24/E23 -> 9.9193709 | F27: =F24/F23 -> 6.2477894 | G27: =G24/G23 -> 3.2514463
B29: Eicher Motors | C29: 46106 | D29: 46105 | E29: 46104 | F29: 46103 | G29: 46102
B30: Total Current Liabilities | C30: 4016.44 | D30: 3359.9 | E30: 3045.07 | F30: 2878.87 | G30: 2428.71
B31: Total Current Assets | C31: 6788.16 | D31: 3874.61 | E31: 3499.91 | F31: 5497.8 | G31: 8747.69
B32: Working Capital | C32: =C31-C30 -> 2771.72 | D32: =D31-D30 -> 514.71 | E32: =E31-E30 -> 454.84 | F32: =F31-F30 -> 2618.93 | G32: =G31-G30 -> 6318.98
B33: Net Sales | C33: 18451.46 | D33: 16078.16 | E33: 14066.64 | F33: 10122.86 | G33: 8619.04
B34: Inventory Turnover Ratio | C34: 16.69 | D34: 15.05 | E34: 15.44 | F34: 11.27 | G34: 11.21
B35: Debtors Turnover Ratio | C35: 17.32 | D35: 18.36 | E35: 15.03 | F35: 14.2 | G35: 44.18
B36: Working Capital Turnover Ratio | C36: =C33/C32 -> 6.6570433 | D36: =D33/D32 -> 31.237318 | E36: =E33/E32 -> 30.926568 | F36: =F33/F32 -> 3.8652656 | G36: =G33/G32 -> 1.3639923
B38: TVS Motor Co | C38: 46106 | D38: 46105 | E38: 46104 | F38: 46103 | G38: 46102
B39: Total Current Liabilities | C39: 8449.24 | D39: 6606.8 | E39: 6008.54 | F39: 5186.5 | G39: 4585.41
B40: Total Current Assets | C40: 5081.87 | D40: 4217.82 | E40: 3667.5 | F40: 3362.28 | G40: 3446.79
B41: Working Capital | C41: =C40-C39 -> -3367.37 | D41: =D40-D39 -> -2388.98 | E41: =E40-E39 -> -2341.04 | F41: =F40-F39 -> -1824.22 | G41: =G40-G39 -> -1138.62
B42: Net Sales | C42: 36251.32 | D42: 31776.37 | E42: 26378.09 | F42: 20790.51 | G42: 16750.54
B43: Inventory Turnover Ratio | C43: 21.01 | D43: 23.18 | E43: 21.34 | F43: 18.52 | G43: 14.54
B44: Debtors Turnover Ratio | C44: 28.08 | D44: 28.16 | E44: 27.68 | F44: 22.84 | G44: 15.57
B45: Working Capital Turnover Ratio | C45: =C42/C41 -> -10.76547 | D45: =D42/D41 -> -13.301229 | E45: =E42/E41 -> -11.26768 | F45: =F42/F41 -> -11.396931 | G45: =G42/G41 -> -14.711265

Sheet IT Sector Analysis
A1: IT SECTOR - WORKING CAPITAL ANALYSIS
A3: 1. WORKING CAPITAL TURNOVER RATIO
A4: Company | B4: FY 2025 | C4: FY 2024 | D4: FY 2023 | E4: FY 2022 | F4: FY 2021 | G4: 5-Year Avg
A5: TCS | B5: 3.9801597 | C5: 3.9022504 | D5: 3.5606809 | E5: 2.8484305 | F5: 2.4885696 | G5: =AVERAGE(B5:F5) -> 3.3560182
A6: Infosys | B6: 3.0082368 | C6: 2.9392468 | D6: 5.0330357 | E6: 3.7850042 | F6: 2.8020874 | G6: =AVERAGE(B6:F6) -> 3.5135222
A7: HCL | B7: 3.407 | C7: 2.5217756 | D7: 2.5846738 | E7: 2.2774042 | F7: 2.0159932 | G7: =AVERAGE(B7:F7) -> 2.5613694
A8: Wipro | B8: 1.7832757 | C8: 2.0795681 | D8: 1.9283734 | E8: 2.0831302 | F8: 1.846046 | G8: =AVERAGE(B8:F8) -> 1.9440787
A9: Tech Mahindra | B9: 6.3592594 | C9: 5.3003097 | D9: 5.5053043 | E9: 3.3621304 | F9: 2.1083371 | G9: =AVERAGE(B9:F9) -> 4.5270682
A10: Sector Average | B10: =AVERAGE(B5:B9) -> 3.7075863 | C10: =AVERAGE(C5:C9) -> 3.3486301 | D10: =AVERAGE(D5:D9) -> 3.7224136 | E10: =AVERAGE(E5:E9) -> 2.8712199 | F10: =AVERAGE(F5:F9) -> 2.2522067 | G10: =AVERAGE(G5:G9) -> 3.1804113
A12: 2. INVENTORY TURNOVER RATIO
A13: Company | B13: FY 2025 | C13: FY 2024 | D13: FY 2023 | E13: FY 2022 | F13: FY 2021 | G13: 5-Year Avg
A14: TCS | B14: 10742.65 | C14: 7494.78 | D14: 7050.15 | E14: 8439 | F14: 19423.29 | G14: =AVERAGE(B14:F14) -> 10629.974
A15: Infosys | B15: 0 | C15: 0 | D15: 0 | E15: 0 | F15: 0 | G15: =AVERAGE(B15:F15) -> 0
A16: HCL | B16: 4258.75 | C16: 1924.72 | D16: 1322.17 | E16: 1766.87 | F16: 1981.83 | G16: =AVERAGE(B16:F16) -> 2250.868
A17: Wipro | B17: 1081.88 | C17: 916.22 | D17: 742.1 | E17: 680.85 | F17: 552.74 | G17: =AVERAGE(B17:F17) -> 794.758
A18: Tech Mahindra | B18: 0 | C18: 0 | D18: 0 | E18: 0 | F18: 0 | G18: =AVERAGE(B18:F18) -> 0
A19: Sector Average | B19: =AVERAGE(B14:B18) -> 3216.656 | C19: =AVERAGE(C14:C18) -> 2067.144 | D19: =AVERAGE(D14:D18) -> 1822.884 | E19: =AVERAGE(E14:E18) -> 2177.344 | F19: =AVERAGE(F14:F18) -> 4391.572 | G19: =AVERAGE(G14:G18) -> 2735.12
A21: 3. DEBTORS TURNOVER RATIO
A22: Company | B22: FY 2025 | C22: FY 2024 | D22: FY 2023 | E22: FY 2022 | F22: FY 2021 | G22: 5-Year Avg
A23: TCS | B23: 4.39 | C23: 4.55 | D23: 5.24 | E23: 5.82 | F23: 5.05 | G23: =AVERAGE(B23:F23) -> 5.01
A24: Infosys | B24: 5.3 | C24: 5.61 | D24: 6.24 | E24: 5.88 | F24: 5.39 | G24: =AVERAGE(B24:F24) -> 5.684
A25: HCL | B25: 3.81 | C25: 3.84 | D25: 3.85 | E25: 4.97 | F25: 5.61 | G25: =AVERAGE(B25:F25) -> 4.416
A26: Wipro | B26: 6.82 | C26: 5.36 | D26: 6 | E26: 6.87 | F26: 5.81 | G26: =AVERAGE(B26:F26) -> 6.172
A27: Tech Mahindra | B27: 4.63 | C27: 4.25 | D27: 4.26 | E27: 4.69 | F27: 5.22 | G27: =AVERAGE(B27:F27) -> 4.61
A28: Sector Average | B28: =AVERAGE(B23:B27) -> 4.99 | C28: =AVERAGE(C23:C27) -> 4.722 | D28: =AVERAGE(D23:D27) -> 5.118 | E28: =AVERAGE(E23:E27) -> 5.646 | F28: =AVERAGE(F23:F27) -> 5.416 | G28: =AVERAGE(G23:G27) -> 5.1784

Sheet Auto Sector Analysis
A1: AUTOMOBILE SECTOR - WORKING CAPITAL ANALYSIS
A3: 1. WORKING CAPITAL TURNOVER RATIO
A4: Company | B4: FY 2025 | C4: FY 2024 | D4: FY 2023 | E4: FY 2022 | F4: FY 2021 | G4: 5-Year Avg
A5: Maruti Suzuki | B5: -43.794176 | C5: -27.279213 | D5: -13.8272 | E5: -379.76602 | F5: 29.063017 | G5: =AVERAGE(B5:F5) -> -87.120719
A6: M & M | B6: 7.474516 | C6: 10.820957 | D6: 9.8749204 | E6: 8.0939343 | F6: 8.6966305 | G6: =AVERAGE(B6:F6) -> 8.9921917
A7: Bajaj Auto | B7: 11.302889 | C7: 27.389383 | D7: 9.9193709 | E7: 6.2477894 | F7: 3.2514463 | G7: =AVERAGE(B7:F7) -> 11.622176
A8: Eicher Motors | B8: 6.6570433 | C8: 31.237318 | D8: 30.926568 | E8: 3.8652656 | F8: 1.3639923 | G8: =AVERAGE(B8:F8) -> 14.810037
A9: TVS Motor Co | B9: -10.76547 | C9: -13.301229 | D9: -11.26768 | E9: -11.396931 | F9: -14.711265 | G9: =AVERAGE(B9:F9) -> -12.288515
A10: Sector Average | B10: =AVERAGE(B5:B9) -> -5.8250396 | C10: =AVERAGE(C5:C9) -> 5.7734432 | D10: =AVERAGE(D5:D9) -> 5.1251958 | E10: =AVERAGE(E5:E9) -> -74.591193 | F10: =AVERAGE(F5:F9) -> 5.5327642 | G10: =AVERAGE(G5:G9) -> -12.796966
A12: 2. INVENTORY TURNOVER RATIO
A13: Company | B13: FY 2025 | C13: FY 2024 | D13: FY 2023 | E13: FY 2022 | F13: FY 2021 | G13: 5-Year Avg
A14: Maruti Suzuki | B14: 29.65 | C14: 34.21 | D14: 27.43 | E14: 24.99 | F14: 23.06 | G14: =AVERAGE(B14:F14) -> 27.868
A15: M & M | B15: 11.27 | C15: 10.39 | D15: 9.57 | E15: 9.76 | F15: 11.39 | G15: =AVERAGE(B15:F15) -> 10.476
A16: Bajaj Auto | B16: 25.54 | C16: 26.35 | D16: 26.06 | E16: 26.94 | F16: 18.57 | G16: =AVERAGE(B16:F16) -> 24.692
A17: Eicher Motors | B17: 16.69 | C17: 15.05 | D17: 15.44 | E17: 11.27 | F17: 11.21 | G17: =AVERAGE(B17:F17) -> 13.932
A18: TVS Motor Co | B18: 21.01 | C18: 23.18 | D18: 21.34 | E18: 18.52 | F18: 14.54 | G18: =AVERAGE(B18:F18) -> 19.718
A19: Sector Average | B19: =AVERAGE(B14:B18) -> 20.832 | C19: =AVERAGE(C14:C18) -> 21.836 | D19: =AVERAGE(D14:D18) -> 19.968 | E19: =AVERAGE(E14:E18) -> 18.296 | F19: =AVERAGE(F14:F18) -> 15.754 | G19: =AVERAGE(G14:G18) -> 19.3372
A21: 3. DEBTORS TURNOVER RATIO
A22: Company | B22: FY 2025 | C22: FY 2024 | D22: FY 2023 | E22: FY 2022 | F22: FY 2021 | G22: 5-Year Avg
A23: Maruti Suzuki | B23: 27.27 | C23: 35.69 | D23: 44.13 | E23: 53.4 | F23: 43.26 | G23: =AVERAGE(B23:F23) -> 40.75
A24: M & M | B24: 22.67 | C24: 22.99 | D24: 24.01 | E24: 21.36 | F24: 16.86 | G24: =AVERAGE(B24:F24) -> 21.578
A25: Bajaj Auto | B25: 22.71 | C25: 22.92 | D25: 22.13 | E25: 15.66 | F25: 12.49 | G25: =AVERAGE(B25:F25) -> 19.182
A26: Eicher Motors | B26: 17.32 | C26: 18.36 | D26: 15.03 | E26: 14.2 | F26: 44.18 | G26: =AVERAGE(B26:F26) -> 21.818
A27: TVS Motor Co | B27: 28.08 | C27: 28.16 | D27: 27.68 | E27: 22.84 | F27: 15.57 | G27: =AVERAGE(B27:F27) -> 24.466
A28: Sector Average | B28: =AVERAGE(B23:B27) -> 23.61 | C28: =AVERAGE(C23:C27) -> 25.624 | D28: =AVERAGE(D23:D27) -> 26.596 | E28: =AVERAGE(E23:E27) -> 25.492 | F28: =AVERAGE(F23:F27) -> 26.472 | G28: =AVERAGE(G23:G27) -> 25.5588

Sheet Sector Comparison
A1: SECTOR-WISE COMPARATIVE ANALYSIS
A3: 1. AVERAGE RATIOS COMPARISON (5-Year Average)
A4: Ratio | B4: IT Sector | C4: Automobile Sector | D4: Better Performance
A5: Working Capital Turnover Ratio | B5: ='IT Sector Analysis'!G10 -> 3.1804113 | C5: ='Auto Sector Analysis'!G10 -> -12.796966 | D5: =IF(B5>C5,"IT Sector","Automobile Sector") -> IT Sector
A6: Inventory Turnover Ratio | B6: ='IT Sector Analysis'!G19 -> 2735.12 | C6: ='Auto Sector Analysis'!G19 -> 19.3372 | D6: =IF(B6>C6,"IT Sector","Automobile Sector") -> IT Sector
A7: Debtors Turnover Ratio | B7: ='IT Sector Analysis'!G28 -> 5.1784 | C7: ='Auto Sector Analysis'!G28 -> 25.5588 | D7: =IF(B7>C7,"IT Sector","Automobile Sector") -> Automobile Sector
A9: 2. YEAR-WISE TREND COMPARISON
A11: Working Capital Turnover Ratio - Year-wise
A12: Year | B12: IT Sector Avg | C12: Auto Sector Avg | D12: Better Performance
A13: FY 2025 | B13: 3.7075863 | C13: -5.8250396 | D13: =IF(B13>C13,"IT Sector","Automobile Sector") -> IT Sector
A14: FY 2024 | B14: 3.3486301 | C14: 5.7734432 | D14: =IF(B14>C14,"IT Sector","Automobile Sector") -> Automobile Sector
A15: FY 2023 | B15: 3.7224136 | C15: 5.1251958 | D15: =IF(B15>C15,"IT Sector","Automobile Sector") -> Automobile Sector
A16: FY 2022 | B16: 2.8712199 | C16: -74.591193 | D16: =IF(B16>C16,"IT Sector","Automobile Sector") -> IT Sector
A17: FY 2021 | B17: 2.2522067 | C17: 5.5327642 | D17: =IF(B17>C17,"IT Sector","Automobile Sector") -> Automobile Sector
A19: Inventory Turnover Ratio - Year-wise
A20: Year | B20: IT Sector Avg | C20: Auto Sector Avg | D20: Better Performance
A21: FY 2025 | B21: 3216.656 | C21: 20.832 | D21: =IF(B21>C21,"IT Sector","Automobile Sector") -> IT Sector
A22: FY 2024 | B22: 2067.144 | C22: 21.836 | D22: =IF(B22>C22,"IT Sector","Automobile Sector") -> IT Sector
A23: FY 2023 | B23: 1822.884 | C23: 19.968 | D23: =IF(B23>C23,"IT Sector","Automobile Sector") -> IT Sector
A24: FY 2022 | B24: 2177.344 | C24: 18.296 | D24: =IF(B24>C24,"IT Sector","Automobile Sector") -> IT Sector
A25: FY 2021 | B25: 4391.572 | C25: 15.754 | D25: =IF(B25>C25,"IT Sector","Automobile Sector") -> IT Sector
A27: Debtors Turnover Ratio - Year-wise
A28: Year | B28: IT Sector Avg | C28: Auto Sector Avg | D28: Better Performance
A29: FY 2025 | B29: 4.99 | C29: 23.61 | D29: =IF(B29>C29,"IT Sector","Automobile Sector") -> Automobile Sector
A30: FY 2024 | B30: 4.722 | C30: 25.624 | D30: =IF(B30>C30,"IT Sector","Automobile Sector") -> Automobile Sector
A31: FY 2023 | B31: 5.118 | C31: 26.596 | D31: =IF(B31>C31,"IT Sector","Automobile Sector") -> Automobile Sector
A32: FY 2022 | B32: 5.646 | C32: 25.492 | D32: =IF(B32>C32,"IT Sector","Automobile Sector") -> Automobile Sector
A33: FY 2021 | B33: 5.416 | C33: 26.472 | D33: =IF(B33>C33,"IT Sector","Automobile Sector") -> Automobile Sector

Sheet Statistical Analysis
A1: DESCRIPTIVE STATISTICS - IT SECTOR
A3: Working Capital Turnover Ratio
A4: Statistical Measure | B4: TCS | C4: Infosys | D4: HCL | E4: Wipro | F4: Tech Mahindra | G4: Sector
A5: Mean | B5: =AVERAGE('IT Sector Analysis'!B5:F5) -> 3.3560182 | C5: =AVERAGE('IT Sector Analysis'!C5:G5) -> 3.2311899 | D5: =AVERAGE('IT Sector Analysis'!D5:H5) -> 3.0634248 | E5: =AVERAGE('IT Sector Analysis'!E5:I5) -> 2.8976728 | F5: =AVERAGE('IT Sector Analysis'!F5:J5) -> 2.9222939 | G5: =AVERAGE('IT Sector Analysis'!B10:F10) -> 3.1804113
A6: Median | B6: =MEDIAN('IT Sector Analysis'!B5:F5) -> 3.5606809 | C6: =MEDIAN('IT Sector Analysis'!C5:G5) -> 3.3560182 | D6: =MEDIAN('IT Sector Analysis'!D5:H5) -> 3.1022243 | E6: =MEDIAN('IT Sector Analysis'!E5:I5) -> 2.8484305 | F6: =MEDIAN('IT Sector Analysis'!F5:J5) -> 2.9222939 | G6: =MEDIAN('IT Sector Analysis'!B10:F10) -> 3.3486301
A7: Std Deviation | B7: =_xlfn.STDEV.S('IT Sector Analysis'!B5:F5) -> 0.6595304 | C7: =_xlfn.STDEV.S('IT Sector Analysis'!C5:G5) -> 0.56401647 | D7: =_xlfn.STDEV.S('IT Sector Analysis'!D5:H5) -> 0.4863317 | E7: =_xlfn.STDEV.S('IT Sector Analysis'!E5:I5) -> 0.43581576 | F7: =_xlfn.STDEV.S('IT Sector Analysis'!F5:J5) -> 0.6133788 | G7: =_xlfn.STDEV.S('IT Sector Analysis'!B10:F10) -> 0.62392724
A8: Min | B8: =MIN('IT Sector Analysis'!B5:F5) -> 2.4885696 | C8: =MIN('IT Sector Analysis'!C5:G5) -> 2.4885696 | D8: =MIN('IT Sector Analysis'!D5:H5) -> 2.4885696 | E8: =MIN('IT Sector Analysis'!E5:I5) -> 2.4885696 | F8: =MIN('IT Sector Analysis'!F5:J5) -> 2.4885696 | G8: =MIN('IT Sector Analysis'!B10:F10) -> 2.2522067
A9: Max | B9: =MAX('IT Sector Analysis'!B5:F5) -> 3.9801597 | C9: =MAX('IT Sector Analysis'!C5:G5) -> 3.9022504 | D9: =MAX('IT Sector Analysis'!D5:H5) -> 3.5606809 | E9: =MAX('IT Sector Analysis'!E5:I5) -> 3.3560182 | F9: =MAX('IT Sector Analysis'!F5:J5) -> 3.3560182 | G9: =MAX('IT Sector Analysis'!B10:F10) -> 3.7224136
A10: Range | B10: =MAX('IT Sector Analysis'!B5:F5)-MIN('IT Sector Analysis'!B5:F5) -> 1.4915901 | C10: 2.2309483 | D10: 1.3910068 | E10: 0.29985454 | F10: 4.2509224 | G10: =MAX('IT Sector Analysis'!B10:F10)-MIN('IT Sector Analysis'!B10:F10) -> 1.470207
A13: Inventory Turnover Ratio
A14: Statistical Measure | B14: TCS | C14: Infosys | D14: HCL | E14: Wipro | F14: Tech Mahindra | G14: Sector
A15: Mean | B15: =AVERAGE('IT Sector Analysis'!B14:F14) -> 10629.974 | C15: =AVERAGE('IT Sector Analysis'!C14:G14) -> 10607.439 | D15: =AVERAGE('IT Sector Analysis'!D14:H14) -> 11385.604 | E15: =AVERAGE('IT Sector Analysis'!E14:I14) -> 12830.755 | F15: =AVERAGE('IT Sector Analysis'!F14:J14) -> 15026.632 | G15: =AVERAGE('IT Sector Analysis'!B19:F19) -> 2735.12
A16: Median | B16: =MEDIAN('IT Sector Analysis'!B14:F14) -> 8439 | C16: =MEDIAN('IT Sector Analysis'!C14:G14) -> 8439 | D16: =MEDIAN('IT Sector Analysis'!D14:H14) -> 9534.487 | E16: =MEDIAN('IT Sector Analysis'!E14:I14) -> 10629.974 | F16: =MEDIAN('IT Sector Analysis'!F14:J14) -> 15026.632 | G16: =MEDIAN('IT Sector Analysis'!B19:F19) -> 2177.344
A17: Std Deviation | B17: =_xlfn.STDEV.S('IT Sector Analysis'!B14:F14) -> 5118.1064 | C17: =_xlfn.STDEV.S('IT Sector Analysis'!C14:G14) -> 5117.7343 | D17: =_xlfn.STDEV.S('IT Sector Analysis'!D14:H14) -> 5557.3978 | E17: =_xlfn.STDEV.S('IT Sector Analysis'!E14:I14) -> 5813.4528 | F17: =_xlfn.STDEV.S('IT Sector Analysis'!F14:J14) -> 6217.8134 | G17: =_xlfn.STDEV.S('IT Sector Analysis'!B19:F19) -> 1068.3153
A18: Min | B18: =MIN('IT Sector Analysis'!B14:F14) -> 7050.15 | C18: =MIN('IT Sector Analysis'!C14:G14) -> 7050.15 | D18: =MIN('IT Sector Analysis'!D14:H14) -> 7050.15 | E18: =MIN('IT Sector Analysis'!E14:I14) -> 8439 | F18: =MIN('IT Sector Analysis'!F14:J14) -> 10629.974 | G18: =MIN('IT Sector Analysis'!B19:F19) -> 1822.884
A19: Max | B19: =MAX('IT Sector Analysis'!B14:F14) -> 19423.29 | C19: =MAX('IT Sector Analysis'!C14:G14) -> 19423.29 | D19: =MAX('IT Sector Analysis'!D14:H14) -> 19423.29 | E19: =MAX('IT Sector Analysis'!E14:I14) -> 19423.29 | F19: =MAX('IT Sector Analysis'!F14:J14) -> 19423.29 | G19: =MAX('IT Sector Analysis'!B19:F19) -> 4391.572
A20: Range | B20: =MAX('IT Sector Analysis'!B14:F14)-MIN('IT Sector Analysis'!B14:F14) -> 12373.14 | C20: =MAX('IT Sector Analysis'!C14:G14)-MIN('IT Sector Analysis'!C14:G14) -> 12373.14 | D20: =MAX('IT Sector Analysis'!D14:H14)-MIN('IT Sector Analysis'!D14:H14) -> 12373.14 | E20: =MAX('IT Sector Analysis'!E14:I14)-MIN('IT Sector Analysis'!E14:I14) -> 10984.29 | F20: =MAX('IT Sector Analysis'!F14:J14)-MIN('IT Sector Analysis'!F14:J14) -> 8793.316 | G20: =MAX('IT Sector Analysis'!B19:F19)-MIN('IT Sector Analysis'!B19:F19) -> 2568.688
A23: Debtors Turnover Ratio
A24: Statistical Measure | B24: TCS | C24: Infosys | D24: HCL | E24: Wipro | F24: Tech Mahindra | G24: Sector
A25: Mean | B25: =AVERAGE('IT Sector Analysis'!B23:F23) -> 5.01 | C25: =AVERAGE('IT Sector Analysis'!C23:G23) -> 5.134 | D25: =AVERAGE('IT Sector Analysis'!D23:H23) -> 5.28 | E25: =AVERAGE('IT Sector Analysis'!E23:I23) -> 5.2933333 | F25: =AVERAGE('IT Sector Analysis'!F23:J23) -> 5.03 | G25: =AVERAGE('IT Sector Analysis'!B28:F28) -> 5.1784
A26: Median | B26: =MEDIAN('IT Sector Analysis'!B23:F23) -> 5.05 | C26: =MEDIAN('IT Sector Analysis'!C23:G23) -> 5.05 | D26: =MEDIAN('IT Sector Analysis'!D23:H23) -> 5.145 | E26: =MEDIAN('IT Sector Analysis'!E23:I23) -> 5.05 | F26: =MEDIAN('IT Sector Analysis'!F23:J23) -> 5.03 | G26: =MEDIAN('IT Sector Analysis'!B28:F28) -> 5.118
A27: Std Deviation | B27: =_xlfn.STDEV.S('IT Sector Analysis'!B23:F23) -> 0.57153303 | C27: =_xlfn.STDEV.S('IT Sector Analysis'!C23:G23) -> 0.45970643 | D27: =_xlfn.STDEV.S('IT Sector Analysis'!D23:H23) -> 0.37372004 | E27: =_xlfn.STDEV.S('IT Sector Analysis'!E23:I23) -> 0.456545 | F27: =_xlfn.STDEV.S('IT Sector Analysis'!F23:J23) -> 0.028284271 | G27: =_xlfn.STDEV.S('IT Sector Analysis'!B28:F28) -> 0.36143713
A28: Min | B28: =MIN('IT Sector Analysis'!B23:F23) -> 4.39 | C28: =MIN('IT Sector Analysis'!C23:G23) -> 4.55 | D28: =MIN('IT Sector Analysis'!D23:H23) -> 5.01 | E28: =MIN('IT Sector Analysis'!E23:I23) -> 5.01 | F28: =MIN('IT Sector Analysis'!F23:J23) -> 5.01 | G28: =MIN('IT Sector Analysis'!B28:F28) -> 4.722
A29: Max | B29: =MAX('IT Sector Analysis'!B23:F23) -> 5.82 | C29: =MAX('IT Sector Analysis'!C23:G23) -> 5.82 | D29: =MAX('IT Sector Analysis'!D23:H23) -> 5.82 | E29: =MAX('IT Sector Analysis'!E23:I23) -> 5.82 | F29: =MAX('IT Sector Analysis'!F23:J23) -> 5.05 | G29: =MAX('IT Sector Analysis'!B28:F28) -> 5.646
A30: Range | B30: =MAX('IT Sector Analysis'!B23:F23)-MIN('IT Sector Analysis'!B23:F23) -> 1.43 | C30: =MAX('IT Sector Analysis'!C23:G23)-MIN('IT Sector Analysis'!C23:G23) -> 1.27 | D30: =MAX('IT Sector Analysis'!D23:H23)-MIN('IT Sector Analysis'!D23:H23) -> 0.81 | E30: =MAX('IT Sector Analysis'!E23:I23)-MIN('IT Sector Analysis'!E23:I23) -> 0.81 | F30: =MAX('IT Sector Analysis'!F23:J23)-MIN('IT Sector Analysis'!F23:J23) -> 0.04 | G30: =MAX('IT Sector Analysis'!B28:F28)-MIN('IT Sector Analysis'!B28:F28) -> 0.924
A34: DESCRIPTIVE STATISTICS - AUTOMOBILE SECTOR
A36: Working Capital Turnover Ratio
A37: Statistical Measure | B37: Maruti Suzuki | C37: M & M | D37: Bajaj Auto | E37: Eicher Motors | F37: TVS Motor Co | G37: Sector
A38: Mean | B38: =AVERAGE('Auto Sector Analysis'!B5:F5) -> -87.120719 | C38: =AVERAGE('Auto Sector Analysis'!C5:G5) -> -95.786027 | D38: =AVERAGE('Auto Sector Analysis'!D5:H5) -> -112.91273 | E38: =AVERAGE('Auto Sector Analysis'!E5:I5) -> -145.94124 | F38: =AVERAGE('Auto Sector Analysis'!F5:J5) -> -29.028851 | G38: =AVERAGE('Auto Sector Analysis'!B10:F10) -> -12.796966
A39: Median | B39: =MEDIAN('Auto Sector Analysis'!B5:F5) -> -27.279213 | C39: =MEDIAN('Auto Sector Analysis'!C5:G5) -> -27.279213 | D39: =MEDIAN('Auto Sector Analysis'!D5:H5) -> -50.473959 | E39: =MEDIAN('Auto Sector Analysis'!E5:I5) -> -87.120719 | F39: =MEDIAN('Auto Sector Analysis'!F5:J5) -> -29.028851 | G39: =MEDIAN('Auto Sector Analysis'!B10:F10) -> 5.1251958
A40: Std Deviation | B40: =_xlfn.STDEV.S('Auto Sector Analysis'!B5:F5) -> 165.80868 | C40: =_xlfn.STDEV.S('Auto Sector Analysis'!C5:G5) -> 164.10168 | D40: =_xlfn.STDEV.S('Auto Sector Analysis'!D5:H5) -> 184.25613 | E40: =_xlfn.STDEV.S('Auto Sector Analysis'!E5:I5) -> 210.66605 | F40: =_xlfn.STDEV.S('Auto Sector Analysis'!F5:J5) -> 82.154307 | G40: =_xlfn.STDEV.S('Auto Sector Analysis'!B10:F10) -> 34.889745
A41: Min | B41: =MIN('Auto Sector Analysis'!B5:F5) -> -379.76602 | C41: =MIN('Auto Sector Analysis'!C5:G5) -> -379.76602 | D41: =MIN('Auto Sector Analysis'!D5:H5) -> -379.76602 | E41: =MIN('Auto Sector Analysis'!E5:I5) -> -379.76602 | F41: =MIN('Auto Sector Analysis'!F5:J5) -> -87.120719 | G41: =MIN('Auto Sector Analysis'!B10:F10) -> -74.591193
A42: Max | B42: =MAX('Auto Sector Analysis'!B5:F5) -> 29.063017 | C42: =MAX('Auto Sector Analysis'!C5:G5) -> 29.063017 | D42: =MAX('Auto Sector Analysis'!D5:H5) -> 29.063017 | E42: =MAX('Auto Sector Analysis'!E5:I5) -> 29.063017 | F42: =MAX('Auto Sector Analysis'!F5:J5) -> 29.063017 | G42: =MAX('Auto Sector Analysis'!B10:F10) -> 5.7734432
A43: Range | B43: =MAX('Auto Sector Analysis'!B5:F5)-MIN('Auto Sector Analysis'!B5:F5) -> 408.82904 | C43: =MAX('Auto Sector Analysis'!C5:G5)-MIN('Auto Sector Analysis'!C5:G5) -> 408.82904 | D43: =MAX('Auto Sector Analysis'!D5:H5)-MIN('Auto Sector Analysis'!D5:H5) -> 408.82904 | E43: =MAX('Auto Sector Analysis'!E5:I5)-MIN('Auto Sector Analysis'!E5:I5) -> 408.82904 | F43: =MAX('Auto Sector Analysis'!F5:J5)-MIN('Auto Sector Analysis'!F5:J5) -> 116.18374 | G43: =MAX('Auto Sector Analysis'!B10:F10)-MIN('Auto Sector Analysis'!B10:F10) -> 80.364636
A46: Inventory Turnover Ratio
A47: Statistical Measure | B47: Maruti Suzuki | C47: M & M | D47: Bajaj Auto | E47: Eicher Motors | F47: TVS Motor Co | G47: Sector
A48: Mean | B48: =AVERAGE('Auto Sector Analysis'!B14:F14) -> 27.868 | C48: =AVERAGE('Auto Sector Analysis'!C14:G14) -> 27.5116 | D48: =AVERAGE('Auto Sector Analysis'!D14:H14) -> 25.837 | E48: =AVERAGE('Auto Sector Analysis'!E14:I14) -> 25.306 | F48: =AVERAGE('Auto Sector Analysis'!F14:J14) -> 25.464 | G48: =AVERAGE('Auto Sector Analysis'!B19:F19) -> 19.3372
A49: Median | B49: =MEDIAN('Auto Sector Analysis'!B14:F14) -> 27.43 | C49: =MEDIAN('Auto Sector Analysis'!C14:G14) -> 27.43 | D49: =MEDIAN('Auto Sector Analysis'!D14:H14) -> 26.21 | E49: =MEDIAN('Auto Sector Analysis'!E14:I14) -> 24.99 | F49: =MEDIAN('Auto Sector Analysis'!F14:J14) -> 25.464 | G49: =MEDIAN('Auto Sector Analysis'!B19:F19) -> 19.968
A50: Std Deviation | B50: =_xlfn.STDEV.S('Auto Sector Analysis'!B14:F14) -> 4.3297829 | C50: =_xlfn.STDEV.S('Auto Sector Analysis'!C14:G14) -> 4.2183365 | D50: =_xlfn.STDEV.S('Auto Sector Analysis'!D14:H14) -> 2.242896 | E50: =_xlfn.STDEV.S('Auto Sector Analysis'!E14:I14) -> 2.4195264 | F50: =_xlfn.STDEV.S('Auto Sector Analysis'!F14:J14) -> 3.3997694 | G50: =_xlfn.STDEV.S('Auto Sector Analysis'!B19:F19) -> 2.3874545
A51: Min | B51: =MIN('Auto Sector Analysis'!B14:F14) -> 23.06 | C51: =MIN('Auto Sector Analysis'!C14:G14) -> 23.06 | D51: =MIN('Auto Sector Analysis'!D14:H14) -> 23.06 | E51: =MIN('Auto Sector Analysis'!E14:I14) -> 23.06 | F51: =MIN('Auto Sector Analysis'!F14:J14) -> 23.06 | G51: =MIN('Auto Sector Analysis'!B19:F19) -> 15.754
...
